<?xml version="1.0"?>

<robot xmlns:xacro="http://www.ros.org/wiki/xacro" name="barista_robot">
  
  <xacro:include filename="$(find barista_robot_description)/xacro/standoff.xacro" />
  <xacro:include filename="$(find barista_robot_description)/xacro/wheel.xacro" />
  <xacro:include filename="$(find barista_robot_description)/xacro/cup_holder_tray.xacro" />
  
  <xacro:arg name="include_laser" default="true"/>
  <xacro:arg name="robot_name" default=""/>
  <xacro:arg name="color" default="blue"/>

  <xacro:property name="robot_name" value="$(arg robot_name)"/>
  <xacro:property name="color" value="$(arg color)"/>
  <xacro:if value="${robot_name == ''}">
    <xacro:property name="prefix" value=""/>
  </xacro:if>
  <xacro:unless value="${robot_name == ''}">
    <xacro:property name="prefix" value="${robot_name}_"/>
  </xacro:unless>

  <material name="gray">
      <color rgba="0.5 0.5 0.5 1"/>
  </material>

  <material name="blue">
      <color rgba="0.0 0.0 1.0 1"/>
  </material>

  <material name="red">
      <color rgba="1.0 0.0 0.0 1"/>
  </material>

  <material name="black">
      <color rgba="0.0 0.0 0.0 1"/>
  </material>

  <link name="${prefix}base_link">
  </link>

  <!-- Chassis -->
  <joint name="${prefix}base_link_to_chassis" type="fixed">
    <origin rpy="0 0 0" xyz="0 0 0" />
    <parent link="${prefix}base_link"/>
    <child link="${prefix}chassis"/>
  </joint>

  <xacro:macro name="chassis" params="color name">
    <xacro:if value="${color == 'blue'}">
      <gazebo reference="${name}">
        <material>Gazebo/Blue</material>
      </gazebo>
    </xacro:if>

    <xacro:if value="${color == 'red'}">
      <gazebo reference="${name}">
        <material>Gazebo/Red</material>
      </gazebo>
    </xacro:if>

    <link name="${name}">
      <visual>
        <origin rpy="0 0 0" xyz="0 0 0"/>
        <geometry>
          <cylinder length="0.155" radius="0.178"/>
        </geometry>
        <material name="${color}"/>
      </visual>
      <collision>
        <origin rpy="0 0 0" xyz="0 0 0"/>
        <geometry>
          <cylinder length="0.155" radius="0.178"/>
        </geometry>
      </collision>
      <inertial>
        <origin rpy="0 0 0" xyz="0 0 0"/>
        <mass value="5"/>
        <inertia ixx="0.04961541666666667" ixy="0.0" ixz="0.0" iyy="0.04961541666666667" iyz="0.0" izz="0.07920999999999999"/>
      </inertial>
    </link>
  </xacro:macro>

  <xacro:chassis name="${prefix}chassis" color="${color}"/>

  <!-- Left Wheel -->
  <joint name="${prefix}chassis_to_left_wheel" type="continuous">  
    <origin rpy="1.57 0 0" xyz="0.0 0.150 -0.0775"/>
    <parent link="${prefix}chassis"/>
    <child link="${prefix}left_wheel"/>
    <axis rpy="0 0 0" xyz="0 0 1"/>
    <limit effort="10000" velocity="1000"/>
    <joint_properties damping="1.0" friction="1.0"/>
  </joint>

  <xacro:wheel wheel_name="${prefix}left_wheel" />

  <!-- Right Wheel -->
  <joint name="${prefix}chassis_to_right_wheel" type="continuous">  
    <origin rpy="1.57 0 0" xyz="0.0 -0.150 -0.0775"/>
    <parent link="${prefix}chassis"/>
    <child link="${prefix}right_wheel"/>
    <axis rpy="0 0 0" xyz="0 0 1"/>
    <limit effort="10000" velocity="1000"/>
    <joint_properties damping="1.0" friction="1.0"/>
  </joint>

  <xacro:wheel wheel_name="${prefix}right_wheel" />

  <!-- Caster Wheel Front -->
  <joint name="${prefix}front_yaw_joint" type="continuous">
    <origin rpy="0 0 0" xyz="0.130 0.0 -0.0775" />
    <parent link="${prefix}chassis" />
    <child link="${prefix}front_yaw_link" />
    <axis xyz="0 0 1" />
    <limit effort="1000.0" velocity="100.0" />
    <dynamics damping="0.0" friction="0.1"/>
  </joint>

  <link name="${prefix}front_yaw_link">
      <visual>
        <origin rpy="0 1.5707 1.5707" xyz="0 0 0"/>
        <geometry>          
          <cylinder length="0.001" radius="0.0045000000000000005"/>
        </geometry>
        <material name="black"/>
      </visual>
      <collision>
        <origin rpy="0 1.5707 1.5707" xyz="0 0 0"/>
        <geometry>
          <cylinder length="0.001" radius="0.0045000000000000005"/>
        </geometry>
      </collision>
      <inertial>
          <origin rpy="0 1.5707 1.5707" xyz="0 0 0"/>
          <mass value="0.001"/>
          <inertia ixx="5.145833333333334e-09" ixy="0" ixz="0" iyy="5.145833333333334e-09" iyz="0" izz="1.0125000000000003e-08"/>
      </inertial>
  </link>

  <joint name="${prefix}front_roll_joint" type="continuous">
    <origin rpy="0 0 0" xyz="0 0 0" />
    <parent link="${prefix}front_yaw_link" />
    <child link="${prefix}front_roll_link" />
    <axis xyz="1 0 0" />
    <limit effort="1000.0" velocity="100.0" />
    <dynamics damping="0.0" friction="0.1"/>
  </joint>

  <link name="${prefix}front_roll_link">
      <visual>
        <origin rpy="0 1.5707 1.5707" xyz="0 0 0"/>
        <geometry>
          <cylinder length="0.001" radius="0.0045000000000000005"/>
        </geometry>
        <material name="black"/>
      </visual>
      <collision>
        <origin rpy="0 1.5707 1.5707" xyz="0 0 0"/>
        <geometry>
          <cylinder length="0.001" radius="0.0045000000000000005"/>
        </geometry>
      </collision>
      <inertial>
          <origin rpy="0 1.5707 1.5707" xyz="0 0 0"/>
          <mass value="0.001"/>
          <inertia ixx="5.145833333333334e-09" ixy="0" ixz="0" iyy="5.145833333333334e-09" iyz="0" izz="1.0125000000000003e-08"/>
      </inertial>
  </link>

  <joint name="${prefix}front_pitch_joint" type="continuous">
    <origin rpy="0 0 0" xyz="0 0 0" />
    <parent link="${prefix}front_roll_link" />
    <child link="${prefix}front_pitch_link" />
    <axis xyz="0 1 0" />
    <limit effort="1000.0" velocity="100.0" />
    <dynamics damping="0.0" friction="0.1"/>
  </joint>

  <gazebo reference="{prefix}front_pitch_link">
    <kp>1000000000000000000000000000.0</kp>
    <kd>1000000000000000000000000000.0</kd>
    <mu1>0.5</mu1>
    <mu2>0.5</mu2>
    <material>Gazebo/Black</material>
  </gazebo>

  <link name="${prefix}front_pitch_link">
    <visual>
      <origin rpy="0 1.5707 1.5707" xyz="0 0 0"/>
      <geometry>
        <sphere radius="0.0352"/>
      </geometry>
      <material name="black"/>
    </visual>
    <collision>
      <origin rpy="0 1.5707 1.5707" xyz="0 0 0"/>
      <geometry>
        <sphere radius="0.0352"/>
      </geometry>
    </collision>
    <inertial>
        <origin rpy="0 1.5707 1.5707" xyz="0 0 0"/>
        <mass value="0.001"/>
        <inertia ixx="5e-07" ixy="0" ixz="0" iyy="5e-07" iyz="0" izz="5e-07"/>
    </inertial>
  </link>

  <!-- Caster Wheel Back -->
  <joint name="${prefix}back_yaw_joint" type="continuous">
    <origin rpy="0 0 0" xyz="-0.130 0.0 -0.0775" />
    <parent link="${prefix}chassis" />
    <child link="${prefix}back_yaw_link" />
    <axis xyz="0 0 1" />
    <limit effort="1000.0" velocity="100.0" />
    <dynamics damping="0.0" friction="0.1"/>
  </joint>  

  <link name="${prefix}back_yaw_link">
      <visual>
        <origin rpy="0 1.5707 1.5707" xyz="0 0 0"/>
        <geometry>          
          <cylinder length="0.001" radius="0.0045000000000000005"/>
        </geometry>
        <material name="black"/>
      </visual>
      <collision>
        <origin rpy="0 1.5707 1.5707" xyz="0 0 0"/>
        <geometry>
          <cylinder length="0.001" radius="0.0045000000000000005"/>
        </geometry>
      </collision>
      <inertial>
          <origin rpy="0 1.5707 1.5707" xyz="0 0 0"/>
          <mass value="0.001"/>
          <inertia ixx="5.145833333333334e-09" ixy="0" ixz="0" iyy="5.145833333333334e-09" iyz="0" izz="1.0125000000000003e-08"/>
      </inertial>
  </link>

  <joint name="${prefix}back_roll_joint" type="continuous">
    <origin rpy="0 0 0" xyz="0 0 0" />
    <parent link="${prefix}back_yaw_link" />
    <child link="${prefix}back_roll_link" />
    <axis xyz="1 0 0" />
    <limit effort="1000.0" velocity="100.0" />
    <dynamics damping="0.0" friction="0.1"/>
  </joint>

  <link name="${prefix}back_roll_link">
      <visual>
        <origin rpy="0 1.5707 1.5707" xyz="0 0 0"/>
        <geometry>
          <cylinder length="0.001" radius="0.0045000000000000005"/>
        </geometry>
        <material name="black"/>
      </visual>
      <collision>
        <origin rpy="0 1.5707 1.5707" xyz="0 0 0"/>
        <geometry>
          <cylinder length="0.001" radius="0.0045000000000000005"/>
        </geometry>
      </collision>
      <inertial>
          <origin rpy="0 1.5707 1.5707" xyz="0 0 0"/>
          <mass value="0.001"/>
          <inertia ixx="5.145833333333334e-09" ixy="0" ixz="0" iyy="5.145833333333334e-09" iyz="0" izz="1.0125000000000003e-08"/>
      </inertial>
  </link>

  <joint name="${prefix}back_pitch_joint" type="continuous">
    <origin rpy="0 0 0" xyz="0 0 0" />
    <parent link="${prefix}back_roll_link" />
    <child link="${prefix}back_pitch_link" />
    <axis xyz="0 1 0" />
    <limit effort="1000.0" velocity="100.0" />
    <dynamics damping="0.0" friction="0.1"/>
  </joint>

  <gazebo reference="{prefix}back_pitch_link">
    <kp>1000000000000000000000000000.0</kp>
    <kd>1000000000000000000000000000.0</kd>
    <mu1>0.5</mu1>
    <mu2>0.5</mu2>
    <material>Gazebo/Black</material>
  </gazebo>

  <link name="${prefix}back_pitch_link">
    <visual>
      <origin rpy="0 1.5707 1.5707" xyz="0 0 0"/>
      <geometry>
        <sphere radius="0.0352"/>
      </geometry>
      <material name="black"/>
    </visual>
    <collision>
      <origin rpy="0 1.5707 1.5707" xyz="0 0 0"/>
      <geometry>
        <sphere radius="0.0352"/>
      </geometry>
    </collision>
    <inertial>
        <origin rpy="0 1.5707 1.5707" xyz="0 0 0"/>
        <mass value="0.001"/>
        <inertia ixx="5e-07" ixy="0" ixz="0" iyy="5e-07" iyz="0" izz="5e-07"/>
    </inertial>
  </link>

  <!-- Cup Holder Tray -->
  <joint name="${prefix}chassis_to_cup_holder_tray" type="fixed">
    <origin rpy="0 0 0" xyz="0 0 0.3425" />
    <parent link="${prefix}base_link"/>
    <child link="${prefix}cup_holder_tray"/>
  </joint>

  <xacro:cup_holder_tray cup_holder_tray_name="${prefix}cup_holder_tray" color="${color}"/>

  <!-- Standoff Rod Back Left -->
  <joint name="${prefix}chassis_to_standoff_rod_back_left" type="fixed">
    <origin rpy="0 0 0" xyz="-0.030 0.140 0.1875" />
    <parent link="${prefix}chassis"/>
    <child link="${prefix}standoff_rod_back_left"/>
  </joint>

  <xacro:standoff standoff_name="${prefix}standoff_rod_back_left"/>

  <!-- Standoff Rod Back Right -->
  <joint name="${prefix}chassis_to_standoff_rod_back_right" type="fixed">
    <origin rpy="0 0 0" xyz="-0.030 -0.140 0.1875" />
    <parent link="${prefix}chassis"/>
    <child link="${prefix}standoff_rod_back_right"/>
  </joint>

  <xacro:standoff standoff_name="${prefix}standoff_rod_back_right"/>

  <!-- Standoff Rod Front Left -->
  <joint name="${prefix}chassis_to_standoff_rod_front_left" type="fixed">
    <origin rpy="0 0 0" xyz="0.030 0.140 0.1875"/>
    <parent link="${prefix}chassis"/>
    <child link="${prefix}standoff_rod_front_left"/>
  </joint>

  <xacro:standoff standoff_name="${prefix}standoff_rod_front_left"/>  

  <!-- Standoff Rod Front Right -->
  <joint name="${prefix}chassis_to_standoff_rod_front_right" type="fixed">
    <origin rpy="0 0 0" xyz="0.030 -0.140 0.1875"/>
    <parent link="${prefix}chassis"/>
    <child link="${prefix}standoff_rod_front_right"/>
  </joint>

  <xacro:standoff standoff_name="${prefix}standoff_rod_front_right"/>

  <!--Laser-->
  <joint name="${prefix}chassis_to_laser_scan_link" type="fixed">
    <origin rpy="0 0 3.14" xyz="0.0 0.0 0.0775"/>
    <parent link="${prefix}chassis"/>
    <child link="${prefix}laser_scan_link"/>
  </joint>

  <link name="${prefix}laser_scan_link">
    <visual>
      <origin rpy="0 0 0" xyz="0 0 0"/>
      <geometry>
        <mesh filename="package://barista_robot_description/meshes/hokuyo_uam05lp.dae" scale="1.0 1.0 1.0"/>
      </geometry>
    </visual>
    <collision>
      <origin rpy="0 0 0" xyz="0 0 0"/>
      <geometry>
        <!--from datasheet-->
        <box size="0.08 0.08 0.095"/>
      </geometry>
    </collision>
    <inertial>
      <!--from datasheet-->
      <mass value="0.8"/>
      <origin rpy="0 0 0" xyz="0 0 0.0"/>
      <!--based on the collision geometry-->
      <inertia ixx="0.0010283333333333334" ixy="0" ixz="0" iyy="0.0010283333333333334" iyz="0" izz="0.0008533333"/>
    </inertial>
  </link>

  <joint name="${prefix}laser_scan_link_to_laser_scan_frame" type="fixed">
    <origin rpy="0 0 0" xyz="0 0 0.08"/>
    <parent link="${prefix}laser_scan_link"/>
    <child link="${prefix}laser_scan_frame"/>
  </joint>

  <link name="${prefix}laser_scan_frame">
  </link>
  
  <xacro:macro name="laser" params="include_laser">
    <xacro:if value="${include_laser}">
      <gazebo reference="${prefix}laser_scan_frame">
        <sensor name="sensor_ray" type="ray">
          <pose>0 0 0 0 0 0</pose>
          <ray>
            <scan>
              <horizontal>
                <samples>200</samples>
                <resolution>1.0</resolution>
                <min_angle>-2,35619</min_angle>
                <max_angle>2,35619</max_angle>
              </horizontal>
            </scan>
            <range>
              <min>0.1</min>
              <max>5.0</max>
            </range>
          </ray>
          <always_on>true</always_on>
          <visualize>true</visualize>
          <update_rate>33</update_rate>
          <plugin name="laser" filename="libgazebo_ros_ray_sensor.so">
            <ros>
              <namespace>/${robot_name}</namespace>
              <remapping>~/out:=scan</remapping>
            </ros>
            <output_type>sensor_msgs/LaserScan</output_type>
          </plugin>
        </sensor>
      </gazebo>
    </xacro:if>
  </xacro:macro>

  <xacro:laser include_laser="$(arg include_laser)"/>

  <!-- Joint Publisher -->
  <gazebo>
    <plugin name="barista_robot_joint_state" filename="libgazebo_ros_joint_state_publisher.so">
      <ros>
          <namespace>/${robot_name}</namespace>
          <remapping>~/out:=joint_states</remapping>
      </ros>
      <update_rate>30</update_rate>
      <joint_name>${prefix}chassis_to_left_wheel</joint_name>
      <joint_name>${prefix}chassis_to_right_wheel</joint_name>
      <joint_name>${prefix}front_yaw_joint</joint_name>
      <joint_name>${prefix}front_roll_joint</joint_name>
      <joint_name>${prefix}front_pitch_joint</joint_name>
      <joint_name>${prefix}back_yaw_joint</joint_name>
      <joint_name>${prefix}back_roll_joint</joint_name>
      <joint_name>${prefix}back_pitch_joint</joint_name>
    </plugin>
  </gazebo>

  <!-- Differential drive -->
  <gazebo>
    <plugin filename="libgazebo_ros_diff_drive.so" name="differential_drive_controller">
      <ros>
        <namespace>/${robot_name}</namespace>
        <remapping>/cmd_vel:=cmd_vel</remapping>
      </ros>
      <!-- wheels -->
      <left_joint>${prefix}chassis_to_left_wheel</left_joint>
      <right_joint>${prefix}chassis_to_right_wheel</right_joint>

      <!-- kinematics -->
      <wheel_separation>0.300</wheel_separation>
      <wheel_diameter>0.0704</wheel_diameter>

      <!-- limits -->
      <max_wheel_torque>1.0</max_wheel_torque>
      <max_wheel_acceleration>2.0</max_wheel_acceleration>

      <!-- output -->
      <publish_odom>true</publish_odom>
      <publish_odom_tf>true</publish_odom_tf>

      <odometry_frame>${prefix}odom</odometry_frame>
      <robot_base_frame>${prefix}base_link</robot_base_frame>
    </plugin>
  </gazebo>
</robot>